I'm sorry, but an uncaught exception occurred.

While running game code:
  File "game/script.rpy", line 94, in script call
    call Niko_reflect_1
  File "game/Niko_reflect_1.rpy", line 2, in script
    python:
  File "game/Niko_reflect_1.rpy", line 10, in <module>
    renpy.say(statement2)
TypeError: say() takes at least 2 arguments (1 given)

-- Full Traceback ------------------------------------------------------------

Full traceback:
  File "game/script.rpy", line 94, in script call
    call Niko_reflect_1
  File "game/Niko_reflect_1.rpy", line 2, in script
    python:
  File "/Users/princesssteffykins/Downloads/RENPY PROJECTS/renpy-7.2.2-sdk/renpy/ast.py", line 900, in execute
    renpy.python.py_exec_bytecode(self.code.bytecode, self.hide, store=self.store)
  File "/Users/princesssteffykins/Downloads/RENPY PROJECTS/renpy-7.2.2-sdk/renpy/python.py", line 1930, in py_exec_bytecode
    exec bytecode in globals, locals
  File "game/Niko_reflect_1.rpy", line 10, in <module>
    renpy.say(statement2)
TypeError: say() takes at least 2 arguments (1 given)

Darwin-17.7.0-x86_64-i386-64bit
Ren'Py 7.2.2.491
TestNovel1 1.0
Tue Jul 16 16:21:50 2019
